Workbook
Name BILL1: 'Bill 1 Summary'!$B$5:$B$23
Name BINEY: 'Bill 1 Summary'!$B$4:$B$4
Name CC: Lists!$H$2:$H$12
Name PLACAT: Lists!$J$2:$J$85
Name UOM: Lists!$E$2:$E$20

Sheet Contract Summary
A1: CONTRACT SUMMARY | D1: Date: | E1: 45717 | G1: Week No: | H1: =VLOOKUP(E1,Lists!A2:C4383,2,FALSE) -> 9 | I1: Instructions
A2: CONTRACT DETAILS
A3: Client: | C3: Nurus-Siraj Nigeria Limited
A4: Name of Contract: | C4: PROPOSED CONSTRUCTION OF 15 SPAN, DUAL CARRIAGEWAY, 6TH BRIDGE OVER RIVER KADUNA AND APPROACH ROADS
A5: Short Name: | C5: 6TH BRIDGE OVER RIVER KADUNA
A6: Original Contract Amount: | C6: 4.6171489e+09 | D6: NAIRA
A7: Current Contract Amount: | C7: 4.6171489e+09 | D7: NAIRA | E7: RETC: | F7: No | J7: =C7-'BEME & Works Completed Fd'!J194 -> 4.6171489e+09 | L7: - Check to Detail Sheet
A8: Contract Schedules
A9: • | B9: Date of Contract Award | C9: 44149 | E9: • Works Actually Commenced on Site:
A10: • | B10: Contract Commencement Date: | C10: 44183
A11: • | B11: Original Contract Duration (Months): | C11: 12 | E11: • Duration Already on Site : | H11: =IF(H9=0,0,IF(ISBLANK(E$1),((E$1-H9)/(365/12)),(E$1-H9)/(365/12))) -> 0
A12: • | B12: Original Contract Completion Date: | C12: =ROUNDUP(C10+(365/12)*C11,0) -> 44548
A13: • | B13: Extension of Time Requested (Months): | C13: 0 | E13: =IF(H13>0,"• Remaining to Original Completion Date:","• Overdue to Original completion Date:") -> • Overdue to Original completion Date: | H13: =IF(C12=0,0,IF(ISBLANK(E$1),((C12-E$1)/(365/12)),(C12-E$1)/(365/12))) -> -38.432877
A14: • | B14: Extension of Time Granted (Months): | C14: 0
A15: • | B15: Revised Contract Duration (Months) | C15: =C11+C14 -> 12 | E15: =IF(H15>0,"• Remaining to Revised Completion Date:","• Overdue to Revised completion Date:") -> • Overdue to Revised completion Date: | H15: =IF(C16=0,0,IF(ISBLANK(E$1),((C16-E$1)/(365/12)),(C16-E$1)/(365/12))) -> -38.432877
A16: • | B16: Revised Completion Date: | C16: =ROUNDUP(C12+C14*(365/12),0) -> 44548
A18: VALUE OF WORKS TO DATE
A20: CLIENT POSITION (INCL. VAT) - CERTIFICATES
A21: • | B21: Works Vetted & Certified - Payable to Contractor: | C21: ='[1]Certificate Status'!Y39 -> 1.8799307e+09 | D21: =IF(C$7=0,0,C21/C$7) -> 0.40716268 | K21: =C21-'[1]Certificate Status'!Y39 -> 0 | L21: - Check to Detail Sheet
A22: • | B22: Works submitted and not yet vetted: | C22: ='[1]Certificate Status'!Y40 -> 0 | D22: =IF(C$7=0,0,C22/C$7) -> 0 | K22: =C22-'[1]Certificate Status'!Y40 -> 0 | L22: - Check to Detail Sheet
A23: • | B23: Total value of works submitted: | C23: =SUM(C21:C22) -> 1.8799307e+09 | D23: =IF(C$7=0,0,C23/C$7) -> 0.40716268
A24: • | B24: Add - Retention Money - Deducted | C24: ='[1]Certificate Status'!H35 -> 2.0318186e+08
A25: • | B25: Deduct - Retention Money - Released | C25: ='[1]Certificate Status'!J35 -> 0
A26: • | B26: Add -Total Advance Payment Recovered | C26: 0
A27: • | B27: Total Gross Value of Works Completed & Certified: | C27: =SUM(C23:C26) -> 2.0831126e+09 | D27: =IF(C$7=0,0,C27/C$7) -> 0.4511686 | F27: =C43-C27 -> #VALUE! | G27: =IF(F$27>0,"In Favour of PW","Negative Cash Position") -> #VALUE!
H28: =IF(F$27>0,"- Payments received less works certified"," - Payments Received less work Certified") -> #VALUE!
A29: PW POSITION (INCL. VAT) - WEEKLY PROGRESS REPORTS
A30: • | B30: Add - Bill 1 | C30: ='[1]Weekly Summary'!F9 -> 0
A31: • | B31: Permanent Works Completed | C31: ='[1]Weekly Summary'!F18 -> 10158750 | D31: =IF(C$7=0,0,C31/C$7) -> 0.0022002214
A32: • | B32: Add - Contingencies | C32: ='[1]Weekly Summary'!F22 -> 25372651
A33: • | B33: Total Value of Works Done | C33: =SUM(C30:C32) -> 35531401 | D33: =IF(C$7=0,0,C33/C$7) -> 0.0076955285 | F33: =C43-C33 -> #VALUE! | G33: =IF(F$33>0,"In Favour of PW","Negative Cash Position") -> #VALUE! | K33: =C33-'[1]BEME & Works Completed'!M178 -> 0 | L33: - Check to Detail Sheet
H34: =IF(F$33>0,"- Payments received less works completed"," - Payments Received less work Completed") -> #VALUE!
A35: Total Work in Progress | C35: =C33-C27 -> -2.0475812e+09 | D35: =IF(C35<0,"- Works Certified is greater than physical works Completed","") -> - Works Certified is greater than physical works Completed
A37: PAYMENT STATUS
A39: Payments Received to Date | C39: Gross | D39: Net Amount | F39: % Cont. Value
A40: Advance Payments | C40: =SUMIF('[1]Payments Recieved'!$C$5:$C$37,"Advance",'[1]Payments Recieved'!$D$5:$D$37) -> #VALUE! | D40: =SUMIF('[1]Payments Recieved'!$C$5:$C$37,"Advance",'[1]Payments Recieved'!$J$5:$J$37) -> #VALUE! | F40: =IF(C$7=0,0,C40/C$7) -> #VALUE!
A41: Certficates Paid | C41: =SUMIF('[1]Payments Recieved'!$C$5:$C$37,"Cert",'[1]Payments Recieved'!$D$5:$D$37) -> #VALUE! | D41: =SUMIF('[1]Payments Recieved'!$C$5:$C$37,"Cert",'[1]Payments Recieved'!$J$5:$J$37) -> #VALUE! | F41: =IF(C$7=0,0,C41/C$7) -> #VALUE!
A42: On Account | C42: =SUMIF('[1]Payments Recieved'!$C$5:$C$37,"On Account",'[1]Payments Recieved'!$D$5:$D$37) -> #VALUE! | D42: =SUMIF('[1]Payments Recieved'!$C$5:$C$37,"On Account",'[1]Payments Recieved'!$J$5:$J$37) -> #VALUE! | F42: =IF(C$7=0,0,C42/C$7) -> #VALUE!
A43: Total Payments Received | C43: =SUM(C40:C42) -> #VALUE! | D43: =SUM(D40:D42) -> #VALUE! | F43: =IF(C$7=0,0,C43/C$7) -> #VALUE! | K43: =C43-'[1]Payments Recieved'!D38 -> #VALUE! | L43: - Check to Detail Sheet
A45: Amounts Certified - Not Yet Paid | C45: =C23-SUM(C41:C42) -> #VALUE!
...

Sheet Weekly Summary
A1: WEEKLY WORK SUMMARY | D1: Date: | E1: ='Contract Summary'!E1 -> 45717 | F1: Week No: | G1: =IF(E1=0,0,VLOOKUP(E1,Lists!A2:B5000,2,FALSE)) -> 9 | H1: Instructions
A3: ='Contract Summary'!C4 -> PROPOSED CONSTRUCTION OF 15 SPAN, DUAL CARRIAGEWAY, 6TH BRIDGE OVER RIVER KADUNA AND APPROACH ROADS
A5: Works Completed | C5: BEME | D5: Completed Previously | E5: This Week | F5: Project to Date | G5: % Compl.
A7: CONCRETE APRON WORK
A8: • | B8: Bill 1 | C8: ='BEME & Works Completed Fd'!J24 -> 35500000 | D8: ='BEME & Works Completed Fd'!K24 -> 0 | E8: ='BEME & Works Completed Fd'!L24 -> 0 | F8: =D8+E8 -> 0 | G8: =IF(C8=0,0,F8/C8) -> 0
A9: • | B9: Excavation and Piling | C9: ='BEME & Works Completed Fd'!J36 -> 595098800 | D9: ='BEME & Works Completed Fd'!K36 -> 4.0044645e+08 | E9: ='BEME & Works Completed Fd'!L36 -> 0 | F9: =D9+E9 -> 4.0044645e+08 | G9: =IF(C9=0,0,F9/C9) -> 0.6729075
A10: • | B10: Pile cap, Pier, Pier caps and Abutment | C10: ='BEME & Works Completed Fd'!J55 -> 953352380 | D10: ='BEME & Works Completed Fd'!K55 -> 3.0485608e+08 | E10: ='BEME & Works Completed Fd'!L55 -> 4771872 | F10: =D10+E10 -> 3.0962796e+08 | G10: =IF(C10=0,0,F10/C10) -> 0.32477808
A11: • | B11: Superstructure | C11: ='BEME & Works Completed Fd'!J72 -> 2095531280 | D11: ='BEME & Works Completed Fd'!K72 -> 5.505839e+08 | E11: ='BEME & Works Completed Fd'!L72 -> 17843485 | F11: =D11+E11 -> 5.6842739e+08 | G11: =IF(C11=0,0,F11/C11) -> 0.27125693
A12: • | B12: Pavement | C12: ='BEME & Works Completed Fd'!J84 -> 0 | D12: ='BEME & Works Completed Fd'!K84 -> 0 | E12: ='BEME & Works Completed Fd'!L84 -> 0 | F12: =D12+E12 -> 0 | G12: =IF(C12=0,0,F12/C12) -> 0
A13: • | B13: Miscellanous | C13: ='BEME & Works Completed Fd'!J99 -> 297390000 | D13: ='BEME & Works Completed Fd'!K99 -> 0 | E13: ='BEME & Works Completed Fd'!L99 -> 0 | F13: =D13+E13 -> 0 | G13: =IF(C13=0,0,F13/C13) -> 0
A14: SUB-TOTAL | C14: =SUM(C8:C13) -> 3976872460 | D14: =SUM(D8:D13) -> 1.2558864e+09 | E14: =SUM(E8:E13) -> 22615357 | F14: =SUM(F8:F13) -> 1.2785018e+09 | G14: =IF(C14=0,0,F14/C14) -> 0.32148423
A15: ="Add VAT & State Levies - "&SUM(Lists!$M$4,'BEME & Works Completed Fd'!$C$243:$C$245)*100&"%" -> Add VAT & State Levies - 7.5% | C15: =C14*SUM(Lists!$M$4,'BEME & Works Completed Fd'!$C$243:$C$245) -> 2.9826543e+08 | D15: =D14*SUM(Lists!$M$4,'BEME & Works Completed Fd'!$C$243:$C$245) -> 94191482 | E15: =E14*SUM(Lists!$M$4,'BEME & Works Completed Fd'!$C$243:$C$245) -> 1696151.8 | F15: =F14*SUM(Lists!$M$4,'BEME & Works Completed Fd'!$C$243:$C$245) -> 95887634
A16: Total Works Completed (Incl. VAT) | C16: =SUM(C14:C15) -> 4.2751379e+09 | D16: =SUM(D14:D15) -> 1.3500779e+09 | E16: =SUM(E14:E15) -> 24311509 | F16: =SUM(F14:F15) -> 1.3743894e+09 | G16: =IF(C16=0,0,F16/C16) -> 0.32148423
A18: Contingency | C18: ='BEME & Works Completed Fd'!J126 -> 3.181498e+08 | D18: ='BEME & Works Completed Fd'!K126 -> 0 | E18: ='BEME & Works Completed Fd'!L126 -> 0 | F18: ='BEME & Works Completed Fd'!M126 -> 0 | G18: =IF(C18=0,0,F18/C18) -> 0
A19: ="Add VAT & State Levies - "&SUM(Lists!$M$4,'BEME & Works Completed Fd'!$C$243:$C$245)*100&"%" -> Add VAT & State Levies - 7.5% | C19: =C18*SUM(Lists!$M$4,'BEME & Works Completed Fd'!$C$243:$C$245) -> 23861235 | D19: =D18*SUM(Lists!$M$4,'BEME & Works Completed Fd'!$C$243:$C$245) -> 0 | E19: =E18*SUM(Lists!$M$4,'BEME & Works Completed Fd'!$C$243:$C$245) -> 0 | F19: =F18*SUM(Lists!$M$4,'BEME & Works Completed Fd'!$C$243:$C$245) -> 0
A20: Total Contingency (Incl. VAT) | C20: =SUM(C18:C19) -> 3.4201103e+08 | D20: =SUM(D18:D19) -> 0 | E20: =SUM(E18:E19) -> 0 | F20: =SUM(F18:F19) -> 0 | G20: =IF(C20=0,0,F20/C20) -> 0
A22: Total Works Completed (Incl. VAT) | C22: =C16+C20 -> 4.6171489e+09 | D22: =D16+D20 -> 1.3500779e+09 | E22: =E16+E20 -> 24311509 | F22: =F16+F20 -> 1.3743894e+09 | G22: =G16+G20 -> 0.32148423
A24: Costs to Date | D24: Completed Previously | E24: This Week | F24: Project to Date | G24: % of Total
A25: • | B25: =IF(ISBLANK(Lists!H2),"",Lists!H2) -> Plant | D25: =SUMIF('Cost Report'!$E$5:$E$85,'Weekly Summary'!$B25,'Cost Report'!$I$5:$I$85) -> 1.5772974e+08 | E25: =SUMIF('Cost Report'!$E$5:$E$85,'Weekly Summary'!$B25,'Cost Report'!$J$5:$J$85) -> 3269800 | F25: =SUMIF('Cost Report'!$E$5:$E$85,'Weekly Summary'!$B25,'Cost Report'!$K$5:$K$85) -> 1.6099954e+08 | G25: =IF(F$34=0,0,F25/F$34) -> 0.14888064
A26: • | B26: =IF(ISBLANK(Lists!H3),"",Lists!H3) -> AGO | D26: =SUMIF('Cost Report'!$E$5:$E$85,'Weekly Summary'!$B26,'Cost Report'!$I$5:$I$85) -> 177509365 | E26: =SUMIF('Cost Report'!$E$5:$E$85,'Weekly Summary'!$B26,'Cost Report'!$J$5:$J$85) -> 2412300 | F26: =SUMIF('Cost Report'!$E$5:$E$85,'Weekly Summary'!$B26,'Cost Report'!$K$5:$K$85) -> 179921665 | G26: =IF(F$34=0,0,F26/F$34) -> 0.16637844
A27: • | B27: =IF(ISBLANK(Lists!H4),"",Lists!H4) -> Materials | D27: =SUMIF('Cost Report'!$E$5:$E$85,'Weekly Summary'!$B27,'Cost Report'!$I$5:$I$85) -> 4.5978258e+08 | E27: =SUMIF('Cost Report'!$E$5:$E$85,'Weekly Summary'!$B27,'Cost Report'!$J$5:$J$85) -> 10452897 | F27: =SUMIF('Cost Report'!$E$5:$E$85,'Weekly Summary'!$B27,'Cost Report'!$K$5:$K$85) -> 4.7023547e+08 | G27: =IF(F$34=0,0,F27/F$34) -> 0.43483948
A28: • | B28: =IF(ISBLANK(Lists!H5),"",Lists!H5) -> Sub Contractors | D28: =SUMIF('Cost Report'!$E$5:$E$85,'Weekly Summary'!$B28,'Cost Report'!$I$5:$I$85) -> 34045601 | E28: =SUMIF('Cost Report'!$E$5:$E$85,'Weekly Summary'!$B28,'Cost Report'!$J$5:$J$85) -> 0 | F28: =SUMIF('Cost Report'!$E$5:$E$85,'Weekly Summary'!$B28,'Cost Report'!$K$5:$K$85) -> 34045601 | G28: =IF(F$34=0,0,F28/F$34) -> 0.03148289
A29: • | B29: =IF(ISBLANK(Lists!H6),"",Lists!H6) -> Local Labour | D29: =SUMIF('Cost Report'!$E$5:$E$85,'Weekly Summary'!$B29,'Cost Report'!$I$5:$I$85) -> 78887600 | E29: =SUMIF('Cost Report'!$E$5:$E$85,'Weekly Summary'!$B29,'Cost Report'!$J$5:$J$85) -> 1364500 | F29: =SUMIF('Cost Report'!$E$5:$E$85,'Weekly Summary'!$B29,'Cost Report'!$K$5:$K$85) -> 80252100 | G29: =IF(F$34=0,0,F29/F$34) -> 0.074211291
A30: • | B30: =IF(ISBLANK(Lists!H7),"",Lists!H7) -> Overheads | D30: =SUMIF('Cost Report'!$E$5:$E$85,'Weekly Summary'!$B30,'Cost Report'!$I$5:$I$85) -> 31000000 | E30: =SUMIF('Cost Report'!$E$5:$E$85,'Weekly Summary'!$B30,'Cost Report'!$J$5:$J$85) -> 0 | F30: =SUMIF('Cost Report'!$E$5:$E$85,'Weekly Summary'!$B30,'Cost Report'!$K$5:$K$85) -> 31000000 | G30: =IF(F$34=0,0,F30/F$34) -> 0.02866654
A31: • | B31: =IF(ISBLANK(Lists!H8),"",Lists!H8) -> Site Level Expenses | D31: =SUMIF('Cost Report'!$E$5:$E$85,'Weekly Summary'!$B31,'Cost Report'!$I$5:$I$85) -> 1.243332e+08 | E31: =SUMIF('Cost Report'!$E$5:$E$85,'Weekly Summary'!$B31,'Cost Report'!$J$5:$J$85) -> 612545.95 | F31: =SUMIF('Cost Report'!$E$5:$E$85,'Weekly Summary'!$B31,'Cost Report'!$K$5:$K$85) -> 1.2494575e+08 | G31: =IF(F$34=0,0,F31/F$34) -> 0.11554072
A32: • | B32: =IF(ISBLANK(Lists!H10),"",Lists!H10) | D32: =SUMIF('Cost Report'!$E$5:$E$85,'Weekly Summary'!$B32,'Cost Report'!$I$5:$I$85) -> 0 | E32: =SUMIF('Cost Report'!$E$5:$E$85,'Weekly Summary'!$B32,'Cost Report'!$J$5:$J$85) -> 0 | F32: =SUMIF('Cost Report'!$E$5:$E$85,'Weekly Summary'!$B32,'Cost Report'!$K$5:$K$85) -> 0
A33: • | B33: =IF(ISBLANK(Lists!H11),"",Lists!H11) | D33: =SUMIF('Cost Report'!$E$5:$E$85,'Weekly Summary'!$B33,'Cost Report'!$I$5:$I$85) -> 0 | E33: =SUMIF('Cost Report'!$E$5:$E$85,'Weekly Summary'!$B33,'Cost Report'!$J$5:$J$85) -> 0 | F33: =SUMIF('Cost Report'!$E$5:$E$85,'Weekly Summary'!$B33,'Cost Report'!$K$5:$K$85) -> 0
A34: Total Costs to Date | D34: =SUM(D25:D33) -> 1.0632881e+09 | E34: =SUM(E25:E33) -> 18112042 | F34: =SUM(F25:F33) -> 1.0814001e+09 | G34: =IF(F$34=0,0,F34/F$34) -> 1
A36: Net Earnings - Excluding Bill 1 | D36: =D16-D34 -> 2.8678983e+08 | E36: =E16-E34 -> 6199466.7 | F36: =F16-F34 -> 2.9298929e+08
A37: % Net Earnings | D37: =IF(D16=0,0,D36/D16) -> 0.21242465 | E37: =IF(E16=0,0,E36/E16) -> 0.25500131 | F37: =IF(F16=0,0,F36/F16) -> 0.21317779
A39: WEEKLY PROGRESS
A41: GENERAL REMARKS

Sheet BEME & Works Completed Fd
B1: BEME & Works Completed to date | N1: Instructions
B2: ='Contract Summary'!C4 -> PROPOSED CONSTRUCTION OF 15 SPAN, DUAL CARRIAGEWAY, 6TH BRIDGE OVER RIVER KADUNA AND APPROACH ROADS
B3: ="Updated to the "&TEXT('Contract Summary'!$E$1,"dd mmmm yyyy")&" - Week No. "&'Contract Summary'!$H$1 -> Updated to the 01 March 2025 - Week No. 9
F4: 0 | G4: =F4+E4 -> 0 | H4: =D4-G4 -> 0 | I4: 1 | J4: =I4*D4 -> 0 | L4: =F4*I4 -> 0 | M4: =SUM(K4,L4) -> 0 | N4: =IF(J4=0,0,M4/J4) -> 0
A6: Total Bill No. 1 Carried to Summary | J6: =SUM(J4:J5) -> 0 | K6: =SUM(K4:K5) -> 0 | L6: =SUM(L4:L5) -> 0 | M6: =SUM(M4:M5) -> 0 | N6: =IF(J6=0,0,M6/J6) -> 0
A8: ITEM | B8: DESCRIPTION | C8: UNIT | D8: CONTRACT QTY | E8: PREVIOUS QTY | F8: THIS WEEK QTY | G8: TOTAL QTY COMPLETED | H8: QTY OUTSTANDING | I8: RATE ₦ | J8: CONTRACT AMOUNT | K8: PREVIOUS AMOUNT | L8: THIS WEEK AMOUNT | M8: TOTAL AMOUNT | N8: % OF WORK COMPLETED
A10: 5 | B10: GENERAL
A11: 5.01 | B11: Provide, furnish and maintain office accommodation for the engineer's Representative | C11: P.S | D11: 1 | G11: =F11+E11 -> 0 | H11: =D11-G11 -> 1 | I11: 2500000 | J11: =I11*D11 -> 2500000 | K11: =E11*I11 -> 0 | L11: =F11*I11 -> 0 | M11: =SUM(K11,L11) -> 0 | N11: =IF(J11=0,0,M11/J11) -> 0
A12: 5.02 | B12: Provide equipment, labor and assistance as may be required by the Engineer's Representative | C12: P.S | D12: 1 | G12: =F12+E12 -> 0 | H12: =D12-G12 -> 1 | I12: 2000000 | J12: =I12*D12 -> 2000000 | K12: =E12*I12 -> 0 | L12: =F12*I12 -> 0 | M12: =SUM(K12,L12) -> 0 | N12: =IF(J12=0,0,M12/J12) -> 0
A13: 5.03 | B13: Allow for Survey and Design | C13: P.S | D13: 1 | G13: =F13+E13 -> 0 | H13: =D13-G13 -> 1 | I13: 5000000 | J13: =I13*D13 -> 5000000 | K13: =E13*I13 -> 0 | L13: =F13*I13 -> 0 | M13: =SUM(K13,L13) -> 0 | N13: =IF(J13=0,0,M13/J13) -> 0
A14: 5.04 | B14: Allow for Purchase and maintenance of project vehicles | C14: L.S | D14: 1 | G14: =F14+E14 -> 0 | H14: =D14-G14 -> 1 | I14: 10000000 | J14: =I14*D14 -> 10000000 | K14: =E14*I14 -> 0 | L14: =F14*I14 -> 0 | M14: =SUM(K14,L14) -> 0 | N14: =IF(J14=0,0,M14/J14) -> 0
A15: 5.05 | B15: Provide erect and maintain living accommodation for Resident Engineer, Technical officers and Technical Assistants | C15: P.S | D15: 1 | G15: =F15+E15 -> 0 | H15: =D15-G15 -> 1 | I15: 2000000 | J15: =I15*D15 -> 2000000 | K15: =E15*I15 -> 0 | L15: =F15*I15 -> 0 | M15: =SUM(K15,L15) -> 0 | N15: =IF(J15=0,0,M15/J15) -> 0
A16: 5.06 | B16: Allow for Envoronmental Impact assessment and safety | C16: P.S | D16: 1 | G16: =F16+E16 -> 0 | H16: =D16-G16 -> 1 | I16: 3000000 | J16: =I16*D16 -> 3000000 | K16: =E16*I16 -> 0 | L16: =F16*I16 -> 0 | M16: =SUM(K16,L16) -> 0 | N16: =IF(J16=0,0,M16/J16) -> 0
A17: 5.07 | B17: Allow for insurance of the Engineer and other Highway supervisory Staff against all accidents in connection with operation of the project. | C17: L.S | D17: 1 | G17: =F17+E17 -> 0 | H17: =D17-G17 -> 1 | I17: 0 | J17: =I17*D17 -> 0 | K17: =E17*I17 -> 0 | L17: =F17*I17 -> 0 | M17: =SUM(K17,L17) -> 0 | N17: =IF(J17=0,0,M17/J17) -> 0
A18: 5.08 | B18: Allow for Pavement Evaluation Unit Services | C18: P.S | D18: 1 | G18: =F18+E18 -> 0 | H18: =D18-G18 -> 1 | I18: 0 | J18: =I18*D18 -> 0 | K18: =E18*I18 -> 0 | L18: =F18*I18 -> 0 | M18: =SUM(K18,L18) -> 0 | N18: =IF(J18=0,0,M18/J18) -> 0
A19: 5.09 | B19: Allow for roadway markings and road signs | C19: P.S | D19: 1 | G19: =F19+E19 -> 0 | H19: =D19-G19 -> 1 | I19: 5000000 | J19: =I19*D19 -> 5000000 | K19: =E19*I19 -> 0 | L19: =F19*I19 -> 0 | M19: =SUM(K19,L19) -> 0 | N19: =IF(J19=0,0,M19/J19) -> 0
A20: 5.1 | B20: Allow for cost of progress photographs | C20: P.S | D20: 1 | G20: =F20+E20 -> 0 | H20: =D20-G20 -> 1 | I20: 1000000 | J20: =I20*D20 -> 1000000 | K20: =E20*I20 -> 0 | L20: =F20*I20 -> 0 | M20: =SUM(K20,L20) -> 0 | N20: =IF(J20=0,0,M20/J20) -> 0
A21: 5.11 | B21: Allow for the removal and relocation of existing installations for electricity, telephone, water supply and other utilities | C21: P.S | D21: 1 | G21: =F21+E21 -> 0 | H21: =D21-G21 -> 1 | I21: 0 | J21: =I21*D21 -> 0 | K21: =E21*I21 -> 0 | L21: =F21*I21 -> 0 | M21: =SUM(K21,L21) -> 0 | N21: =IF(J21=0,0,M21/J21) -> 0
A22: 5.12 | B22: Allow for compensation of crop, buildings and other properties affected by the proposed bridge alignment | C22: P.S | D22: 1 | G22: =F22+E22 -> 0 | H22: =D22-G22 -> 1 | I22: 5000000 | J22: =I22*D22 -> 5000000 | K22: =E22*I22 -> 0 | L22: =F22*I22 -> 0 | M22: =SUM(K22,L22) -> 0 | N22: =IF(J22=0,0,M22/J22) -> 0
A24: Total Bill No. 5.0 Carried to Summary | J24: =SUM(J11:J22) -> 35500000 | K24: =SUM(K14:K21) -> 0 | L24: =SUM(L14:L21) -> 0 | M24: =SUM(M14:M21) -> 0 | N24: =IF(J24=0,0,M24/J24) -> 0
A25: 5.1 | B25: EXCAVATION AND PILING
A26: 5.1.1 | B26: Provide and place lateritic material as filling in river to serve as access for river crossing | C26: m3 | D26: 37224 | E26: 27080 | G26: =F26+E26 -> 27080 | H26: =D26-G26 -> 10144 | I26: 6200 | J26: =I26*D26 -> 230788800 | K26: =E26*I26 -> 167896000 | L26: =F26*I26 -> 0 | M26: =SUM(K26,L26) -> 167896000 | N26: =IF(J26=0,0,M26/J26) -> 0.72748764
A27: 5.1.2 | B27: Excavate in any kind of material except rock for all foundations including dewatering, shoring and backfilling with suitable material. | C27: m3 | D27: 4500 | E27: 11617 | G27: =F27+E27 -> 11617 | H27: =D27-G27 -> -7117 | I27: 5300 | J27: =I27*D27 -> 23850000 | K27: =E27*I27 -> 61570100 | L27: =F27*I27 -> 0 | M27: =SUM(K27,L27) -> 61570100 | N27: =IF(J27=0,0,M27/J27) -> 2.5815556
A28: 5.1.3 | B28: Extra over item 5.1.1 for excavation of rock. (haulage inclusive) Provisional | C28: m3 | D28: 1200 | E28: 0 | G28: =F28+E28 -> 0 | H28: =D28-G28 -> 1200 | I28: 32500 | J28: =I28*D28 -> 39000000 | K28: =E28*I28 -> 0 | L28: =F28*I28 -> 0 | M28: =SUM(K28,L28) -> 0 | N28: =IF(J28=0,0,M28/J28) -> 0
A29: 5.1.4 | B29: Earth fill suitable borrowed materials for foundations behind and around abutments | C29: m3 | D29: 4300 | E29: 0 | G29: =F29+E29 -> 0 | H29: =D29-G29 -> 4300 | I29: 6200 | J29: =I29*D29 -> 26660000 | K29: =E29*I29 -> 0 | L29: =F29*I29 -> 0 | M29: =SUM(K29,L29) -> 0 | N29: =IF(J29=0,0,M29/J29) -> 0
A30: 5.1.5 | B30: Grade 15 mass concrete to rock foundation bottom level | C30: m3 | D30: 2000 | E30: 1378.9 | G30: =F30+E30 -> 1378.9 | H30: =D30-G30 -> 621.1 | I30: 121500 | J30: =I30*D30 -> 243000000 | K30: =E30*I30 -> 167536350 | L30: =F30*I30 -> 0 | M30: =SUM(K30,L30) -> 167536350 | N30: =IF(J30=0,0,M30/J30) -> 0.68945
A31: 5.1.6 | B31: Provide, place and fix 25mm dia High tensile steel reinforcement in bottom of foundation ( Micro piles ) | C31: Tons | D31: 10 | E31: 2.91864 | G31: =F31+E31 -> 2.91864 | H31: =D31-G31 -> 7.08136 | I31: 1180000 | J31: =I31*D31 -> 11800000 | K31: =E31*I31 -> 3443995.2 | L31: =F31*I31 -> 0 | M31: =SUM(K31,L31) -> 3443995.2 | N31: =IF(J31=0,0,M31/J31) -> 0.291864
A32: 5.1.7 | B32: Provide and bore tests 600mm nominal diameter piles to any depth. Rate to include driving casting, filing with concrete grade 25, reinforcement and trimming of pile head as specified. | C32: m | D32: rate only | G32: =F32+E32 -> 0 | H32: 0 | I32: 500000 | J32: 0 | K32: =E32*I32 -> 0 | L32: =F32*I32 -> 0 | M32: =SUM(K32,L32) -> 0 | N32: =IF(J32=0,0,M32/J32) -> 0
A33: 5.1.8 | B33: Allow for confirmatory deep soil investigation at bridge site | C33: LS | D33: 1 | G33: =F33+E33 -> 0 | H33: =D33-G33 -> 1 | I33: 20000000 | J33: =I33*D33 -> 20000000 | K33: =E33*I33 -> 0 | L33: =F33*I33 -> 0 | M33: =SUM(K33,L33) -> 0 | N33: =IF(J33=0,0,M33/J33) -> 0
A34: 5.1.9 | B34: Allow for Load tests on 600mm diameter piles to twice the design load | C34: LS | D34: rate only | G34: =F34+E34 -> 0 | H34: 0 | I34: 40000000 | J34: 0 | K34: =E34*I34 -> 0 | L34: =F34*I34 -> 0 | M34: =SUM(K34,L34) -> 0 | N34: =IF(J34=0,0,M34/J34) -> 0
A36: Total Bill No. 2 Carried to Summary | J36: =SUM(J26:J34) -> 595098800 | K36: =SUM(K26:K34) -> 4.0044645e+08 | L36: =SUM(L26:L34) -> 0 | M36: =SUM(M26:M34) -> 4.0044645e+08 | N36: =IF(J36=0,0,M36/J36) -> 0.6729075
A39: ITEM | B39: DESCRIPTION | C39: UNIT | D39: CONTRACT QTY | E39: PREVIOUS QTY | F39: THIS WEEK QTY | G39: TOTAL QTY COMPLETED | H39: QTY OUTSTANDING | I39: RATE ₦ | J39: CONTRACT AMOUNT | K39: PREVIOUS AMOUNT | L39: THIS WEEK AMOUNT | M39: TOTAL AMOUNT | N39: % OF WORK COMPLETED
A41: 5.2 | B41: PILE CAP, PIERS ,PIER CAPS, ABUTMENT AND APPROACH SLAB
A42: 5.2.1 | B42: Provide, mix and place grade 10 mass concrete 100mm blinding for bottom of pile caps and foundations and approach slab | C42: m3 | D42: 125 | E42: 0 | G42: =F42+E42 -> 0 | H42: =D42-G42 -> 125 | I42: 115000 | J42: =I42*D42 -> 14375000 | K42: =E42*I42 -> 0 | L42: =F42*I42 -> 0 | M42: =SUM(K42,L42) -> 0 | N42: =IF(J42=0,0,M42/J42) -> 0
A43: 5.2.2 | B43: Provide, mix and place grade 30 concrete in pile caps and foundations including formwork and shuttering | C43: m3 | D43: 1254 | E43: 686.4 | G43: =F43+E43 -> 686.4 | H43: =D43-G43 -> 567.6 | I43: 180000 | J43: =I43*D43 -> 225720000 | K43: =E43*I43 -> 1.23552e+08 | L43: =F43*I43 -> 0 | M43: =SUM(K43,L43) -> 1.23552e+08 | N43: =IF(J43=0,0,M43/J43) -> 0.54736842
A44: 5.2.3 | B44: Provide, cut and fix high tensile reinforcement in pile caps and foundations. | C44: Tons | D44: 105 | E44: 73.888412 | G44: =F44+E44 -> 73.888412 | H44: =D44-G44 -> 31.111588 | I44: 1180000 | J44: =I44*D44 -> 123900000 | K44: =E44*I44 -> 87188327 | L44: =F44*I44 -> 0 | M44: =SUM(K44,L44) -> 87188327 | N44: =IF(J44=0,0,M44/J44) -> 0.70369917
A45: 5.2.4 | B45: Provide, mix and place grade 30 concrete in abutments, wingwalls, piers, Retaining and pier caps | C45: m3 | D45: 1862 | E45: 344.9048 | F45: 26.5104 | G45: =F45+E45 -> 371.4152 | H45: =D45-G45 -> 1490.5848 | I45: 180000 | J45: =I45*D45 -> 335160000 | K45: =E45*I45 -> 62082864 | L45: =F45*I45 -> 4771872 | M45: =SUM(K45,L45) -> 66854736 | N45: =IF(J45=0,0,M45/J45) -> 0.19947111
A46: 5.2.5 | B46: Provide, cut and fix high tensile reinforcement in Abutment, Wingwalls, Piers and Pier Cap | C46: Tons | D46: 165 | E46: 27.14652 | G46: =F46+E46 -> 27.14652 | H46: =D46-G46 -> 137.85348 | I46: 1180000 | J46: =I46*D46 -> 194700000 | K46: =E46*I46 -> 32032894 | L46: =F46*I46 -> 0 | M46: =SUM(K46,L46) -> 32032894 | N46: =IF(J46=0,0,M46/J46) -> 0.16452436
A47: 5.2.6 | B47: Provide and fix 100 mm diameter PVC pipe as weep holes in abutments and wingwalls as shown the drawings. | C47: Nos. | D47: 144 | G47: =F47+E47 -> 0 | H47: =D47-G47 -> 144 | I47: 6500 | J47: =I47*D47 -> 936000 | K47: =E47*I47 -> 0 | L47: =F47*I47 -> 0 | M47: =SUM(K47,L47) -> 0 | N47: =IF(J47=0,0,M47/J47) -> 0
A48: 5.2.7 | B48: Grade 20 Concrete for Abutment Slope Protection | C48: m2 | D48: 550 | G48: =F48+E48 -> 0 | H48: =D48-G48 -> 550 | I48: 17000 | J48: =I48*D48 -> 9350000 | K48: =E48*I48 -> 0 | L48: =F48*I48 -> 0 | M48: =SUM(K48,L48) -> 0 | N48: =IF(J48=0,0,M48/J48) -> 0
...

Sheet Certificate Status
A1: CERTIFICATES | T1: Date: | U1: ='Weekly Summary'!E1 -> 45717 | V1: Week No: | W1: =IF(U1=0,0,VLOOKUP(U1,Lists!A2:B5000,2,FALSE)) -> 9 | X1: Instructions
A2: ='Contract Summary'!C4 -> PROPOSED CONSTRUCTION OF 15 SPAN, DUAL CARRIAGEWAY, 6TH BRIDGE OVER RIVER KADUNA AND APPROACH ROADS
A3: CERTIFICATES
A4: Date Submitted | B4: Cert Number | C4: Gross Value of Works Done | D4: Add Materials on Site | E4: General Bill 1 | F4: Total Value of Work Done | G4: Value of works per Cert | H4: Total Retention Held | I4: Retention This Cert | J4: Total Net Payment in Respect of works | K4: Add Release of Retention | L4: Add Value of Contingency Used | M4: Add Fluctuation on Materials | N4: Total Value of Works Executed | O4: Less Previously Certified without VAT | P4: ="Add VAT - "&Lists!$M$4*100&"%" -> Add VAT - 7.5% | Q4: Add Stamp Duty | R4: Add Admin Charge | S4: Educational Levy | T4: Total Amount Due | U4: Less Recovery of Advance | V4: Less advance Payment Refund per Cert | W4: Total Amount of Payment Certified | X4: Status
D5: 0 | F5: =SUM(C5:E5) -> 0 | G5: =F5 -> 0 | I5: =H5 -> 0 | J5: =F5-H5 -> 0 | N5: =SUM(J5:M5) -> 0 | O5: =SUM(K5:N5) -> 0 | P5: =O5*0.05 -> 0 | T5: =SUM(O5:S5) -> 0 | V5: =U5 -> 0 | W5: =T5-U5 -> 0 | X5: Not Vetted
D6: 0 | F6: =SUM(C6:E6) -> 0 | G6: =IF(F6=0,0,SUM(F6)-SUM(G$5:G5)) -> 0 | I6: =IF(H6=0,0,SUM(H6)-SUM(I$5:I5)) -> 0 | J6: =F6-H6 -> 0 | K6: 0 | L6: 0 | M6: 0 | N6: =SUM(J6:M6) -> 0 | O6: =IF(N6=0,0,N6-N5) -> 0 | P6: =O6*0.05 -> 0 | Q6: =O6*0.01 -> 0 | R6: =O6*0.02 -> 0 | T6: =SUM(O6:S6) -> 0 | V6: =IF(U6=0,0,SUM(U6)-SUM(V$5:V5)) -> 0 | W6: =T6-U6 -> 0
D7: 0 | F7: =SUM(C7:E7) -> 0 | G7: =IF(F7=0,0,SUM(F7)-SUM(G$5:G6)) -> 0 | I7: =IF(H7=0,0,SUM(H7)-SUM(I$5:I6)) -> 0 | J7: =F7-H7 -> 0 | K7: 0 | L7: 0 | M7: 0 | N7: =SUM(J7:M7) -> 0 | O7: =IF(N7=0,0,N7-N6) -> 0 | P7: =O7*0.05 -> 0 | Q7: =O7*0.01 -> 0 | R7: =O7*0.02 -> 0 | T7: =SUM(O7:S7) -> 0 | V7: =IF(U7=0,0,SUM(U7)-SUM(V$5:V6)) -> 0 | W7: =T7-U7 -> 0
D8: 0 | F8: =SUM(C8:E8) -> 0 | G8: =IF(F8=0,0,SUM(F8)-SUM(G$5:G7)) -> 0 | I8: =IF(H8=0,0,SUM(H8)-SUM(I$5:I7)) -> 0 | J8: =F8-H8 -> 0 | K8: 0 | L8: 0 | M8: 0 | N8: =SUM(J8:M8) -> 0 | O8: =IF(N8=0,0,N8-N7) -> 0 | P8: =O8*0.05 -> 0 | Q8: =O8*0.01 -> 0 | R8: =O8*0.02 -> 0 | T8: =SUM(O8:S8) -> 0 | V8: =IF(U8=0,0,SUM(U8)-SUM(V$5:V7)) -> 0 | W8: =T8-U8 -> 0
D9: 0 | F9: =SUM(C9:E9) -> 0 | G9: =IF(F9=0,0,SUM(F9)-SUM(G$5:G8)) -> 0 | I9: =IF(H9=0,0,SUM(H9)-SUM(I$5:I8)) -> 0 | J9: =F9-H9 -> 0 | K9: 0 | L9: 0 | M9: 0 | N9: =SUM(J9:M9) -> 0 | O9: =IF(N9=0,0,N9-N8) -> 0 | P9: =O9*0.05 -> 0 | Q9: =O9*0.01 -> 0 | R9: =O9*0.02 -> 0 | T9: =SUM(O9:S9) -> 0 | V9: =IF(U9=0,0,SUM(U9)-SUM(V$5:V8)) -> 0 | W9: =T9-U9 -> 0
D10: 0 | F10: =SUM(C10:E10) -> 0 | G10: =IF(F10=0,0,SUM(F10)-SUM(G$5:G9)) -> 0 | I10: =IF(H10=0,0,SUM(H10)-SUM(I$5:I9)) -> 0 | J10: =F10-H10 -> 0 | K10: 0 | L10: 0 | M10: 0 | N10: =SUM(J10:M10) -> 0 | O10: =IF(N10=0,0,N10-N9) -> 0 | P10: =O10*0.05 -> 0 | Q10: =O10*0.01 -> 0 | R10: =O10*0.02 -> 0 | T10: =SUM(O10:S10) -> 0 | V10: =IF(U10=0,0,SUM(U10)-SUM(V$5:V9)) -> 0 | W10: =T10-U10 -> 0
F11: =SUM(C11:E11) -> 0 | G11: =IF(F11=0,0,SUM(F11)-SUM(G$5:G10)) -> 0 | I11: =IF(H11=0,0,SUM(H11)-SUM(I$5:I10)) -> 0 | J11: =F11-H11 -> 0 | K11: 0 | L11: 0 | M11: 0 | N11: =SUM(J11:M11) -> 0 | O11: =IF(N11=0,0,N11-N10) -> 0 | P11: =O11*0.05 -> 0 | Q11: =O11*0.01 -> 0 | R11: =O11*0.02 -> 0 | T11: =SUM(O11:S11) -> 0 | V11: =IF(U11=0,0,SUM(U11)-SUM(V$5:V10)) -> 0 | W11: =T11-U11 -> 0
F12: =SUM(C12:E12) -> 0 | G12: =IF(F12=0,0,SUM(F12)-SUM(G$5:G11)) -> 0 | I12: =IF(H12=0,0,SUM(H12)-SUM(I$5:I11)) -> 0 | J12: =F12-H12 -> 0 | K12: 0 | L12: 0 | M12: 0 | N12: =SUM(J12:M12) -> 0 | O12: =IF(N12=0,0,N12-N11) -> 0 | P12: =O12*0.05 -> 0 | Q12: =O12*0.01 -> 0 | R12: =O12*0.02 -> 0 | T12: =SUM(O12:S12) -> 0 | V12: =IF(U12=0,0,SUM(U12)-SUM(V$5:V11)) -> 0 | W12: =T12-U12 -> 0
F13: =SUM(C13:E13) -> 0 | G13: =IF(F13=0,0,SUM(F13)-SUM(G$5:G12)) -> 0 | I13: =IF(H13=0,0,SUM(H13)-SUM(I$5:I12)) -> 0 | J13: =F13-H13 -> 0 | K13: 0 | L13: 0 | M13: 0 | N13: =SUM(J13:M13) -> 0 | O13: =IF(N13=0,0,N13-N12) -> 0 | P13: =O13*0.05 -> 0 | Q13: =O13*0.01 -> 0 | R13: =O13*0.02 -> 0 | T13: =SUM(O13:S13) -> 0 | V13: =IF(U13=0,0,SUM(U13)-SUM(V$5:V12)) -> 0 | W13: =T13-U13 -> 0
F14: =SUM(C14:E14) -> 0 | G14: =IF(F14=0,0,SUM(F14)-SUM(G$5:G13)) -> 0 | I14: =IF(H14=0,0,SUM(H14)-SUM(I$5:I13)) -> 0 | J14: =F14-H14 -> 0 | K14: 0 | L14: 0 | M14: 0 | N14: =SUM(J14:M14) -> 0 | O14: =IF(N14=0,0,N14-N13) -> 0 | P14: =O14*0.05 -> 0 | Q14: =O14*0.01 -> 0 | R14: =O14*0.02 -> 0 | T14: =SUM(O14:S14) -> 0 | V14: =IF(U14=0,0,SUM(U14)-SUM(V$5:V13)) -> 0 | W14: =T14-U14 -> 0
F15: =SUM(C15:E15) -> 0 | G15: =IF(F15=0,0,SUM(F15)-SUM(G$5:G14)) -> 0 | I15: =IF(H15=0,0,SUM(H15)-SUM(I$5:I14)) -> 0 | J15: =F15-H15 -> 0 | K15: 0 | L15: 0 | M15: 0 | N15: =SUM(J15:M15) -> 0 | O15: =IF(N15=0,0,N15-N14) -> 0 | P15: =O15*0.05 -> 0 | Q15: =O15*0.01 -> 0 | R15: =O15*0.02 -> 0 | T15: =SUM(O15:S15) -> 0 | V15: =IF(U15=0,0,SUM(U15)-SUM(V$5:V14)) -> 0 | W15: =T15-U15 -> 0
F16: =SUM(C16:E16) -> 0 | G16: =IF(F16=0,0,SUM(F16)-SUM(G$5:G15)) -> 0 | I16: =IF(H16=0,0,SUM(H16)-SUM(I$5:I15)) -> 0 | J16: =F16-H16 -> 0 | K16: 0 | L16: 0 | M16: 0 | N16: =SUM(J16:M16) -> 0 | O16: =IF(N16=0,0,N16-N15) -> 0 | P16: =O16*0.05 -> 0 | Q16: =O16*0.01 -> 0 | R16: =O16*0.02 -> 0 | S16: =O16*0.025 -> 0 | T16: =SUM(O16:S16) -> 0 | V16: =IF(U16=0,0,SUM(U16)-SUM(V$5:V15)) -> 0 | W16: =T16-U16 -> 0
F17: =SUM(C17:E17) -> 0 | G17: =IF(F17=0,0,SUM(F17)-SUM(G$5:G16)) -> 0 | I17: =IF(H17=0,0,SUM(H17)-SUM(I$5:I16)) -> 0 | J17: =F17-H17 -> 0 | K17: 0 | L17: 0 | M17: 0 | N17: =SUM(J17:M17) -> 0 | O17: =IF(N17=0,0,N17-N16) -> 0 | P17: =O17*0.05 -> 0 | Q17: =O17*0.01 -> 0 | R17: =O17*0.02 -> 0 | S17: =O17*0.025 -> 0 | T17: =SUM(O17:S17) -> 0 | V17: =IF(U17=0,0,SUM(U17)-SUM(V$5:V16)) -> 0 | W17: =T17-U17 -> 0
F18: =SUM(C18:E18) -> 0 | G18: =IF(F18=0,0,SUM(F18)-SUM(G$5:G17)) -> 0 | I18: =IF(H18=0,0,SUM(H18)-SUM(I$5:I17)) -> 0 | J18: =F18-H18 -> 0 | N18: =SUM(J18:M18) -> 0 | O18: =IF(N18=0,0,N18-N17) -> 0 | P18: =O18*0.05 -> 0 | Q18: =O18*0.01 -> 0 | R18: =O18*0.02 -> 0 | S18: =O18*0.025 -> 0 | T18: =SUM(O18:S18) -> 0 | V18: =IF(U18=0,0,SUM(U18)-SUM(V$5:V17)) -> 0 | W18: =T18-U18 -> 0
F19: =SUM(C19:E19) -> 0 | G19: =IF(F19=0,0,SUM(F19)-SUM(G$5:G18)) -> 0 | I19: =IF(H19=0,0,SUM(H19)-SUM(I$5:I18)) -> 0 | J19: =F19-H19 -> 0 | N19: =SUM(J19:M19) -> 0 | O19: =IF(N19=0,0,N19-N18) -> 0 | P19: =O19*0.05 -> 0 | Q19: =O19*0.01 -> 0 | R19: =O19*0.02 -> 0 | S19: =O19*0.025 -> 0 | T19: =SUM(O19:S19) -> 0 | V19: =IF(U19=0,0,SUM(U19)-SUM(V$5:V18)) -> 0 | W19: =T19-U19 -> 0
F20: =SUM(C20:E20) -> 0 | G20: =IF(F20=0,0,SUM(F20)-SUM(G$5:G19)) -> 0 | I20: =IF(H20=0,0,SUM(H20)-SUM(I$5:I19)) -> 0 | J20: =F20-H20 -> 0 | N20: =SUM(J20:M20) -> 0 | O20: =IF(N20=0,0,N20-N19) -> 0 | P20: =O20*0.05 -> 0 | Q20: =O20*0.01 -> 0 | R20: =O20*0.02 -> 0 | S20: =O20*0.025 -> 0 | T20: =SUM(O20:S20) -> 0 | V20: =IF(U20=0,0,SUM(U20)-SUM(V$5:V19)) -> 0 | W20: =T20-U20 -> 0
F21: =SUM(C21:E21) -> 0 | G21: =IF(F21=0,0,SUM(F21)-SUM(G$5:G20)) -> 0 | I21: =IF(H21=0,0,SUM(H21)-SUM(I$5:I20)) -> 0 | J21: =F21-H21 -> 0 | N21: =SUM(J21:M21) -> 0 | O21: =IF(N21=0,0,N21-N20) -> 0 | P21: =O21*0.05 -> 0 | Q21: =O21*0.01 -> 0 | R21: =O21*0.02 -> 0 | S21: =O21*0.025 -> 0 | T21: =SUM(O21:S21) -> 0 | V21: =IF(U21=0,0,SUM(U21)-SUM(V$5:V20)) -> 0 | W21: =T21-U21 -> 0
F22: =SUM(C22:E22) -> 0 | G22: =IF(F22=0,0,SUM(F22)-SUM(G$5:G21)) -> 0 | I22: =IF(H22=0,0,SUM(H22)-SUM(I$5:I21)) -> 0 | J22: =F22-H22 -> 0 | N22: =SUM(J22:M22) -> 0 | O22: =IF(N22=0,0,N22-N21) -> 0 | P22: =O22*0.05 -> 0 | Q22: =O22*0.01 -> 0 | R22: =O22*0.02 -> 0 | S22: =O22*0.025 -> 0 | T22: =SUM(O22:S22) -> 0 | V22: =IF(U22=0,0,SUM(U22)-SUM(V$5:V21)) -> 0 | W22: =T22-U22 -> 0
F23: =SUM(C23:E23) -> 0 | G23: =IF(F23=0,0,SUM(F23)-SUM(G$5:G22)) -> 0 | I23: =IF(H23=0,0,SUM(H23)-SUM(I$5:I22)) -> 0 | J23: =F23-H23 -> 0 | N23: =SUM(J23:M23) -> 0 | O23: =IF(N23=0,0,N23-N22) -> 0 | P23: =O23*0.05 -> 0 | Q23: =O23*0.01 -> 0 | R23: =O23*0.02 -> 0 | T23: =SUM(O23:S23) -> 0 | V23: =IF(U23=0,0,SUM(U23)-SUM(V$5:V22)) -> 0 | W23: =T23-U23 -> 0
F24: =SUM(C24:E24) -> 0 | G24: =IF(F24=0,0,SUM(F24)-SUM(G$5:G23)) -> 0 | I24: =IF(H24=0,0,SUM(H24)-SUM(I$5:I23)) -> 0 | J24: =F24-H24 -> 0 | N24: =SUM(J24:M24) -> 0 | O24: =IF(N24=0,0,N24-N23) -> 0 | P24: =O24*0.05 -> 0 | Q24: =O24*0.01 -> 0 | R24: =O24*0.02 -> 0 | T24: =SUM(O24:S24) -> 0 | V24: =IF(U24=0,0,SUM(U24)-SUM(V$5:V23)) -> 0 | W24: =T24-U24 -> 0
F25: =SUM(C25:E25) -> 0 | G25: =IF(F25=0,0,SUM(F25)-SUM(G$5:G24)) -> 0 | I25: =IF(H25=0,0,SUM(H25)-SUM(I$5:I24)) -> 0 | J25: =F25-H25 -> 0 | N25: =SUM(J25:M25) -> 0 | O25: =IF(N25=0,0,N25-N24) -> 0 | P25: =O25*0.05 -> 0 | Q25: =O25*0.01 -> 0 | R25: =O25*0.02 -> 0 | T25: =SUM(O25:S25) -> 0 | V25: =IF(U25=0,0,SUM(U25)-SUM(V$5:V24)) -> 0 | W25: =T25-U25 -> 0
F26: =SUM(C26:E26) -> 0 | G26: =IF(F26=0,0,SUM(F26)-SUM(G$5:G25)) -> 0 | I26: =IF(H26=0,0,SUM(H26)-SUM(I$5:I25)) -> 0 | J26: =F26-H26 -> 0 | N26: =SUM(J26:M26) -> 0 | O26: =IF(N26=0,0,N26-N25) -> 0 | P26: =O26*0.05 -> 0 | Q26: =O26*0.01 -> 0 | R26: =O26*0.02 -> 0 | T26: =SUM(O26:S26) -> 0 | V26: =IF(U26=0,0,SUM(U26)-SUM(V$5:V25)) -> 0 | W26: =T26-U26 -> 0
F27: =SUM(C27:E27) -> 0 | G27: =IF(F27=0,0,SUM(F27)-SUM(G$5:G26)) -> 0 | I27: =IF(H27=0,0,SUM(H27)-SUM(I$5:I26)) -> 0 | J27: =F27-H27 -> 0 | N27: =SUM(J27:M27) -> 0 | O27: =IF(N27=0,0,N27-N26) -> 0 | P27: =O27*0.05 -> 0 | Q27: =O27*0.01 -> 0 | R27: =O27*0.02 -> 0 | T27: =SUM(O27:S27) -> 0 | V27: =IF(U27=0,0,SUM(U27)-SUM(V$5:V26)) -> 0 | W27: =T27-U27 -> 0
F28: =SUM(C28:E28) -> 0 | G28: =IF(F28=0,0,SUM(F28)-SUM(G$5:G27)) -> 0 | I28: =IF(H28=0,0,SUM(H28)-SUM(I$5:I27)) -> 0 | J28: =F28-H28 -> 0 | N28: =SUM(J28:M28) -> 0 | O28: =IF(N28=0,0,N28-N27) -> 0 | P28: =O28*0.05 -> 0 | Q28: =O28*0.01 -> 0 | R28: =O28*0.02 -> 0 | T28: =SUM(O28:S28) -> 0 | V28: =IF(U28=0,0,SUM(U28)-SUM(V$5:V27)) -> 0 | W28: =T28-U28 -> 0
F29: =SUM(C29:E29) -> 0 | G29: =IF(F29=0,0,SUM(F29)-SUM(G$5:G28)) -> 0 | I29: =IF(H29=0,0,SUM(H29)-SUM(I$5:I28)) -> 0 | J29: =F29-H29 -> 0 | N29: =SUM(J29:M29) -> 0 | O29: =IF(N29=0,0,N29-N28) -> 0 | P29: =O29*0.05 -> 0 | Q29: =O29*0.01 -> 0 | R29: =O29*0.02 -> 0 | T29: =SUM(O29:S29) -> 0 | V29: =IF(U29=0,0,SUM(U29)-SUM(V$5:V28)) -> 0 | W29: =T29-U29 -> 0
F30: =SUM(C30:E30) -> 0 | G30: =IF(F30=0,0,SUM(F30)-SUM(G$5:G29)) -> 0 | I30: =IF(H30=0,0,SUM(H30)-SUM(I$5:I29)) -> 0 | J30: =F30-H30 -> 0 | N30: =SUM(J30:M30) -> 0 | O30: =IF(N30=0,0,N30-N29) -> 0 | P30: =O30*0.05 -> 0 | Q30: =O30*0.01 -> 0 | R30: =O30*0.02 -> 0 | T30: =SUM(O30:S30) -> 0 | V30: =IF(U30=0,0,SUM(U30)-SUM(V$5:V29)) -> 0 | W30: =T30-U30 -> 0
F31: =SUM(C31:E31) -> 0 | G31: =IF(F31=0,0,SUM(F31)-SUM(G$5:G30)) -> 0 | I31: =IF(H31=0,0,SUM(H31)-SUM(I$5:I30)) -> 0 | J31: =F31-H31 -> 0 | N31: =SUM(J31:M31) -> 0 | O31: =IF(N31=0,0,N31-N30) -> 0 | P31: =O31*0.05 -> 0 | Q31: =O31*0.01 -> 0 | R31: =O31*0.02 -> 0 | T31: =SUM(O31:S31) -> 0 | V31: =IF(U31=0,0,SUM(U31)-SUM(V$5:V30)) -> 0 | W31: =T31-U31 -> 0
A32: Totals | H32: =SUM(G5:G31) -> 0 | I32: =SUM(I5:I31) -> 0 | K32: =SUM(K5:K31) -> 0 | L32: =SUM(L5:L31) -> 0 | M32: =SUM(M5:M31) -> 0 | N32: =SUM(N5:N31) -> 0 | P32: =SUM(P5:P31) -> 0 | Q32: =SUM(Q5:Q31) -> 0 | R32: =SUM(R5:R31) -> 0 | S32: =SUM(S5:S31) -> 0 | T32: =SUM(T5:T31) -> 0 | V32: =SUM(V5:V31) -> 0 | W32: =SUM(W5:W31) -> 0
H33: ="Add VAT - "&Lists!$M$4*100&"%" -> Add VAT - 7.5% | I33: =I32*Lists!$M$4 -> 0 | K33: =K32*Lists!$M$4 -> 0 | U33: ="Add VAT - "&Lists!$M$4*100&"%" -> Add VAT - 7.5% | V33: 0
H34: Total Retention Deducted - Inc. VAT: | I34: =SUM(I32:I33) -> 0 | J34: Ret. Rel. - Inc VAT: | K34: =SUM(K32:K33) -> 0 | U34: Total Advance Recovered - Including VAT: | V34: =SUM(V32:V33) -> 0
A37: SUMMARY CERT STATUS
A38: Vetted | C38: =SUMIF($X$5:$X$31,$A38,C$5:C$31) -> 0 | D38: =SUMIF($X$5:$X$31,$A38,D$5:D$31) -> 0 | N38: =SUMIF($X$5:$X$31,$A38,N$5:N$31) -> 0 | W38: =SUMIF($X$5:$X$31,$A38,W$5:W$31) -> 0
A39: Not Vetted | C39: =SUMIF($X$5:$X$31,$A39,C$5:C$31) -> 0 | D39: =SUMIF($X$5:$X$31,$A39,D$5:D$31) -> 0 | N39: =SUMIF($X$5:$X$31,$A39,N$5:N$31) -> 0 | W39: =SUMIF($X$5:$X$31,$A39,W$5:W$31) -> 0
C40: =SUM(C38:C39) -> 0 | D40: =SUM(D38:D39) -> 0 | N40: =SUM(N38:N39) -> 0 | W40: =SUM(W38:W39) -> 0

Sheet Payments Recieved
A1: PAYMENTS RECEIVED | F1: Date: | G1: ='Contract Summary'!E1 -> 45717 | I1: Week No: | J1: =IF(G1=0,0,VLOOKUP(G1,Lists!A2:B5000,2,FALSE)) -> 9 | K1: Instructions
A2: ='Contract Summary'!C4 -> PROPOSED CONSTRUCTION OF 15 SPAN, DUAL CARRIAGEWAY, 6TH BRIDGE OVER RIVER KADUNA AND APPROACH ROADS
A3: PAYMENT DETAILS | E3: DEDUCTIONS | L3: Deductions %
A4: Date | B4: Voucher Number | C4: Payment Type | D4: Gross Amount (Including VAT) | E4: WHT | F4: VAT | G4: Vetting Fee | H4: Stamp Duty | I4: Other | J4: Net Amount Payable | L4: VAT % | M4: WHT % | N4: State Levy % | O4: Stamp Duty % | P4: Other %
B5: Advance No. 1 | C5: Advance | D5: 0 | E5: =2.5%*D5 -> 0 | F5: =7.5%*D5 -> 0 | G5: =0.5%*D5 -> 0 | H5: =1%*D5 -> 0 | I5: 0 | J5: =D5-SUM(E5:I5) -> 0 | L5: =IF(D5=0,0,E5/$D5) -> 0 | M5: =IF(E5=0,0,F5/$D5) -> 0 | N5: =IF(F5=0,0,G5/$D5) -> 0 | O5: =IF(G5=0,0,H5/$D5) -> 0 | P5: =IF(H5=0,0,I5/$D5) -> 0
B6: Cert No 2 | C6: Cert | D6: 0 | E6: =2.5%*D6 -> 0 | F6: =7.5%*D6 -> 0 | G6: =0.5%*D6 -> 0 | H6: =1%*D6 -> 0 | I6: 0 | J6: =D6-SUM(E6:I6) -> 0 | L6: =IF(D6=0,0,E6/$D6) -> 0 | M6: =IF(E6=0,0,F6/$D6) -> 0 | N6: =IF(F6=0,0,G6/$D6) -> 0 | O6: =IF(G6=0,0,H6/$D6) -> 0 | P6: =IF(H6=0,0,I6/$D6) -> 0
G7: 0 | H7: 0 | I7: 0 | J7: =D7-SUM(E7:I7) -> 0 | L7: =IF(D7=0,0,E7/$D7) -> 0 | M7: =IF(E7=0,0,F7/$D7) -> 0 | N7: =IF(F7=0,0,G7/$D7) -> 0 | O7: =IF(G7=0,0,H7/$D7) -> 0 | P7: =IF(H7=0,0,I7/$D7) -> 0
G8: 0 | H8: 0 | I8: 0 | J8: =D8-SUM(E8:I8) -> 0 | L8: =IF(D8=0,0,E8/$D8) -> 0 | M8: =IF(E8=0,0,F8/$D8) -> 0 | N8: =IF(F8=0,0,G8/$D8) -> 0 | O8: =IF(G8=0,0,H8/$D8) -> 0 | P8: =IF(H8=0,0,I8/$D8) -> 0
G9: 0 | H9: 0 | I9: 0 | J9: =D9-SUM(E9:I9) -> 0 | L9: =IF(D9=0,0,E9/$D9) -> 0 | M9: =IF(E9=0,0,F9/$D9) -> 0 | N9: =IF(F9=0,0,G9/$D9) -> 0 | O9: =IF(G9=0,0,H9/$D9) -> 0 | P9: =IF(H9=0,0,I9/$D9) -> 0
G10: 0 | H10: 0 | I10: 0 | J10: =D10-SUM(E10:I10) -> 0 | L10: =IF(D10=0,0,E10/$D10) -> 0 | M10: =IF(E10=0,0,F10/$D10) -> 0 | N10: =IF(F10=0,0,G10/$D10) -> 0 | O10: =IF(G10=0,0,H10/$D10) -> 0 | P10: =IF(H10=0,0,I10/$D10) -> 0
E11: =D11/1.05*0.05 -> 0 | G11: 0 | H11: 0 | I11: 0 | J11: =D11-SUM(E11:I11) -> 0 | L11: =IF(D11=0,0,E11/$D11) -> 0 | M11: =IF(E11=0,0,F11/$D11) -> 0 | N11: =IF(F11=0,0,G11/$D11) -> 0 | O11: =IF(G11=0,0,H11/$D11) -> 0 | P11: =IF(H11=0,0,I11/$D11) -> 0
E12: =D12/1.05*0.05 -> 0 | F12: =D12/1.05*0.05 -> 0 | J12: =D12-SUM(E12:I12) -> 0 | L12: =IF(D12=0,0,E12/$D12) -> 0 | M12: =IF(E12=0,0,F12/$D12) -> 0 | N12: =IF(F12=0,0,G12/$D12) -> 0 | O12: =IF(G12=0,0,H12/$D12) -> 0 | P12: =IF(H12=0,0,I12/$D12) -> 0
E13: =D13/1.05*0.05 -> 0 | F13: =D13/1.05*0.05 -> 0 | J13: =D13-SUM(E13:I13) -> 0 | L13: =IF(D13=0,0,E13/$D13) -> 0 | M13: =IF(E13=0,0,F13/$D13) -> 0 | N13: =IF(F13=0,0,G13/$D13) -> 0 | O13: =IF(G13=0,0,H13/$D13) -> 0 | P13: =IF(H13=0,0,I13/$D13) -> 0
J14: =D14-SUM(E14:I14) -> 0 | L14: =IF(D14=0,0,E14/$D14) -> 0 | M14: =IF(E14=0,0,F14/$D14) -> 0 | N14: =IF(F14=0,0,G14/$D14) -> 0 | O14: =IF(G14=0,0,H14/$D14) -> 0 | P14: =IF(H14=0,0,I14/$D14) -> 0
J15: =D15-SUM(E15:I15) -> 0 | L15: =IF(D15=0,0,E15/$D15) -> 0 | M15: =IF(E15=0,0,F15/$D15) -> 0 | N15: =IF(F15=0,0,G15/$D15) -> 0 | O15: =IF(G15=0,0,H15/$D15) -> 0 | P15: =IF(H15=0,0,I15/$D15) -> 0
J16: =D16-SUM(E16:I16) -> 0 | L16: =IF(D16=0,0,E16/$D16) -> 0 | M16: =IF(E16=0,0,F16/$D16) -> 0 | N16: =IF(F16=0,0,G16/$D16) -> 0 | O16: =IF(G16=0,0,H16/$D16) -> 0 | P16: =IF(H16=0,0,I16/$D16) -> 0
J17: =D17-SUM(E17:I17) -> 0 | L17: =IF(D17=0,0,E17/$D17) -> 0 | M17: =IF(E17=0,0,F17/$D17) -> 0 | N17: =IF(F17=0,0,G17/$D17) -> 0 | O17: =IF(G17=0,0,H17/$D17) -> 0 | P17: =IF(H17=0,0,I17/$D17) -> 0
J18: =D18-SUM(E18:I18) -> 0 | L18: =IF(D18=0,0,E18/$D18) -> 0 | M18: =IF(E18=0,0,F18/$D18) -> 0 | N18: =IF(F18=0,0,G18/$D18) -> 0 | O18: =IF(G18=0,0,H18/$D18) -> 0 | P18: =IF(H18=0,0,I18/$D18) -> 0
J19: =D19-SUM(E19:I19) -> 0 | L19: =IF(D19=0,0,E19/$D19) -> 0 | M19: =IF(E19=0,0,F19/$D19) -> 0 | N19: =IF(F19=0,0,G19/$D19) -> 0 | O19: =IF(G19=0,0,H19/$D19) -> 0 | P19: =IF(H19=0,0,I19/$D19) -> 0
J20: =D20-SUM(E20:I20) -> 0 | L20: =IF(D20=0,0,E20/$D20) -> 0 | M20: =IF(E20=0,0,F20/$D20) -> 0 | N20: =IF(F20=0,0,G20/$D20) -> 0 | O20: =IF(G20=0,0,H20/$D20) -> 0 | P20: =IF(H20=0,0,I20/$D20) -> 0
J21: =D21-SUM(E21:I21) -> 0 | L21: =IF(D21=0,0,E21/$D21) -> 0 | M21: =IF(E21=0,0,F21/$D21) -> 0 | N21: =IF(F21=0,0,G21/$D21) -> 0 | O21: =IF(G21=0,0,H21/$D21) -> 0 | P21: =IF(H21=0,0,I21/$D21) -> 0
J22: =D22-SUM(E22:I22) -> 0 | L22: =IF(D22=0,0,E22/$D22) -> 0 | M22: =IF(E22=0,0,F22/$D22) -> 0 | N22: =IF(F22=0,0,G22/$D22) -> 0 | O22: =IF(G22=0,0,H22/$D22) -> 0 | P22: =IF(H22=0,0,I22/$D22) -> 0
J23: =D23-SUM(E23:I23) -> 0 | L23: =IF(D23=0,0,E23/$D23) -> 0 | M23: =IF(E23=0,0,F23/$D23) -> 0 | N23: =IF(F23=0,0,G23/$D23) -> 0 | O23: =IF(G23=0,0,H23/$D23) -> 0 | P23: =IF(H23=0,0,I23/$D23) -> 0
J24: =D24-SUM(E24:I24) -> 0 | L24: =IF(D24=0,0,E24/$D24) -> 0 | M24: =IF(E24=0,0,F24/$D24) -> 0 | N24: =IF(F24=0,0,G24/$D24) -> 0 | O24: =IF(G24=0,0,H24/$D24) -> 0 | P24: =IF(H24=0,0,I24/$D24) -> 0
J25: =D25-SUM(E25:I25) -> 0 | L25: =IF(D25=0,0,E25/$D25) -> 0 | M25: =IF(E25=0,0,F25/$D25) -> 0 | N25: =IF(F25=0,0,G25/$D25) -> 0 | O25: =IF(G25=0,0,H25/$D25) -> 0 | P25: =IF(H25=0,0,I25/$D25) -> 0
... J37: =D37-SUM(E37:I37) -> 0 | L37: =IF(D37=0,0,E37/$D37) -> 0 | M37: =IF(E37=0,0,F37/$D37) -> 0 | N37: =IF(F37=0,0,G37/$D37) -> 0 | O37: =IF(G37=0,0,H37/$D37) -> 0 | P37: =IF(H37=0,0,I37/$D37) -> 0
A38: Total All: | D38: =SUM(D5:D37) -> 0 | E38: =SUM(E5:E37) -> 0 | F38: =SUM(F5:F37) -> 0 | G38: =SUM(G5:G37) -> 0 | H38: =SUM(H5:H37) -> 0 | I38: =SUM(I5:I37) -> 0 | J38: =SUM(J5:J37) -> 0 | L38: =IF(D38=0,0,E38/$D38) -> 0 | M38: =IF(E38=0,0,F38/$D38) -> 0 | N38: =IF(F38=0,0,G38/$D38) -> 0 | O38: =IF(G38=0,0,H38/$D38) -> 0 | P38: =IF(H38=0,0,I38/$D38) -> 0
D40: =D38-D5 -> 0

Sheet Cost Report
C1: COST REPORT | H1: Date: | I1: ='Contract Summary'!E1 -> 45717 | J1: Week No: | K1: =IF(I1=0,0,VLOOKUP(I1,Lists!A2:B5000,2,FALSE)) -> 9 | L1: Instructions
C2: ='[1]Contract Summary'!C4 -> CONSTRUCTION OF BUA LAFIAGI BYPASS ROAD | D2: ='Payments Recieved'!A2 -> PROPOSED CONSTRUCTION OF 15 SPAN, DUAL CARRIAGEWAY, 6TH BRIDGE OVER RIVER KADUNA AND APPROACH ROADS
C3: S/No | D3: Description | E3: Cost Category | F3: Unit | G3: Quantity This Week | H3: Rate N | I3: Amount Previous Week | J3: Amount This Week | K3: Amount Up to Date | M3: Source Legend | N3: Source Detail
C4: PLANT DEPARTMENT | M4: PLANT DEPARTMENT | N4: All information should be obtained from the plant department reports.
C5: 1 | D5: Diesel | E5: AGO | F5: Litres | G5: ='Diesel Consumption'!K91 -> 2193 | H5: 1100 | I5: 177509365 | J5: =G5*H5 -> 2412300 | K5: =I5+J5 -> 179921665 | M5: MATERIALS | N5: All information is auto populated from the materials reconcilaition sheet, other than the Amount Previous Week
C6: 2 | D6: Diesel (P.W. External Issues) | E6: AGO | F6: Litres | H6: =H5 -> 1100 | I6: 0 | J6: ='[1]Diesel Consumption'!O117 -> 0 | K6: =I6+J6 -> 0 | M6: OTHER MATERIALS | N6: Other material not captured on the materails & civils report that may be used on site.
C7: 3 | D7: Plant Internal | E7: Plant | F7: N/a | I7: 1.2189104e+08 | J7: ='Plant Return'!H83 -> 2516666.5 | K7: =I7+J7 -> 1.244077e+08 | M7: OTHER SITE COSTS | N7: All information is auto populated from the headcount and subcontractors report, other than the Amount Previous Week
C8: 4 | D8: Hired Plant/Equipment/Vehicle | E8: Plant | F8: N/a | I8: 813000 | J8: ='Hired Vehicles'!H25 -> 15000 | K8: =I8+J8 -> 828000 | M8: SITE LEVEL ACCOUNTS | N8: All information is obtained from the site accountant weekly financial report.
C9: 5 | D9: Petrol | E9: Plant | F9: Litres | G9: 162.3 | H9: 1000 | I9: 9520945.1 | J9: =G9*H9 -> 162300 | K9: =I9+J9 -> 9683245.1 | M9: OVERHEADS | N9: Information is provided by the PM other than Bill 1 information which is provided by the Accountant in completing the Bill 1 schedule.
C10: 6 | D10: Stores Cost | E10: Plant | F10: Various | J10: 0
C11: 7 | D11: Engine Oil | E11: Plant | F11: Litres | G11: 53 | H11: 4097.56 | I11: 14865204 | J11: =G11*H11 -> 217170.68 | K11: =I11+J11 -> 15082375
C12: 8 | D12: Gear oil | E12: Plant | F12: Litres | G12: 14 | H12: 6786 | I12: 1767586.3 | J12: =G12*H12 -> 95004 | K12: =I12+J12 -> 1862590.3
C13: 9 | D13: ATF 220 Oil | E13: Plant | F13: Litres | G13: 0 | H13: 6171 | I13: 601902.44 | J13: =G13*H13 -> 0 | K13: =I13+J13 -> 601902.44
C14: 10 | D14: Hydroualic Oil Azzolla | E14: Plant | F14: Litres | G14: 33 | H14: 3292.69 | I14: 2334807.1 | J14: =G14*H14 -> 108658.77 | K14: =I14+J14 -> 2443465.8
C15: 11 | D15: Rarius 427 Comp. Oil | E15: Plant | F15: Litres | H15: 0 | I15: 0 | J15: =G15*H15 -> 0 | K15: =I15+J15 -> 0
C16: 12 | D16: Almo 529 | E16: Plant | F16: Litres | H16: 0 | I16: 0 | J16: =G16*H16 -> 0 | K16: =I16+J16 -> 0
C17: 13 | D17: Grease | E17: Plant | F17: Kg | G17: 10 | H17: 12100 | I17: 984180 | J17: =G17*H17 -> 121000 | K17: =I17+J17 -> 1105180
C18: 14 | D18: 6440; Tyres | E18: Plant | F18: Each | I18: 0 | K18: =I18+J18 -> 0
C19: MATERIALS | I19: 0 | J19: =G19*H19 -> 0 | K19: =I19+J19 -> 0
C20: ='[1]Materials & Civils'!A5 -> 1 | D20: Cement (Bags) | E20: Materials | F20: =IF(ISBLANK('[1]Materials & Civils'!C5),"",'[1]Materials & Civils'!C5) -> Bags | G20: ='Materials & Civils'!N5 -> 468 | H20: 4650 | I20: 149870500 | J20: =G20*H20 -> 2176200 | K20: =I20+J20 -> 152046700
C21: ='[1]Materials & Civils'!A6 -> 2 | D21: Cement (Bulk) | E21: Materials | F21: =IF(ISBLANK('[1]Materials & Civils'!C6),"",'[1]Materials & Civils'!C6) -> Tonnes | G21: ='Materials & Civils'!N6 -> 0 | H21: =IF(D21="",0,VLOOKUP(D21,'Materials & Civils'!$B$5:$N$38,3,FALSE)) -> 95000 | I21: 0 | J21: =G21*H21 -> 0 | K21: =I21+J21 -> 0
C22: ='[1]Materials & Civils'!A7 -> 3 | D22: Rebar (10mm) Local | E22: Materials | F22: =IF(ISBLANK('[1]Materials & Civils'!C7),"",'[1]Materials & Civils'!C7) -> Tonnes | G22: ='Materials & Civils'!N7 -> 1.312185 | H22: 550000 | I22: 15191382 | J22: =G22*H22 -> 721701.75 | K22: =I22+J22 -> 15913084
C23: ='[1]Materials & Civils'!A8 -> 4 | D23: Rebar (12mm) Local | E23: Materials | F23: =IF(ISBLANK('[1]Materials & Civils'!C8),"",'[1]Materials & Civils'!C8) -> Tonnes | G23: ='Materials & Civils'!N8 -> 1.5431486 | H23: 550000 | I23: 36252567 | J23: =G23*H23 -> 848731.75 | K23: =I23+J23 -> 37101299
C24: ='[1]Materials & Civils'!A9 -> 5 | D24: Rebar (16mm) Local | E24: Materials | F24: =IF(ISBLANK('[1]Materials & Civils'!C9),"",'[1]Materials & Civils'!C9) -> Tonnes | G24: ='Materials & Civils'!N9 -> 1.5892272 | H24: 550000 | I24: 33672342 | J24: =G24*H24 -> 874074.96 | K24: =I24+J24 -> 34546417
C25: ='[1]Materials & Civils'!A10 -> 6 | D25: Rebar (12mm) Imported | E25: Materials | F25: =IF(ISBLANK('[1]Materials & Civils'!C10),"",'[1]Materials & Civils'!C10) -> Tonnes | G25: ='Materials & Civils'!N10 -> 0 | H25: 550000 | I25: 0 | J25: =G25*H25 -> 0 | K25: =I25+J25 -> 0
C26: ='[1]Materials & Civils'!A11 -> 7 | D26: Rebar (16mm) Imported | E26: Materials | F26: =IF(ISBLANK('[1]Materials & Civils'!C11),"",'[1]Materials & Civils'!C11) -> Tonnes | G26: ='Materials & Civils'!N11 -> 0 | H26: 550000 | I26: 0 | J26: =G26*H26 -> 0 | K26: =I26+J26 -> 0
C27: ='[1]Materials & Civils'!A12 -> 8 | D27: Rebar (20mm) Imported | E27: Materials | F27: =IF(ISBLANK('[1]Materials & Civils'!C12),"",'[1]Materials & Civils'!C12) -> Tonnes | G27: ='Materials & Civils'!N12 -> 0 | H27: 550000 | I27: 0 | J27: =G27*H27 -> 0 | K27: =I27+J27 -> 0
C28: ='[1]Materials & Civils'!A13 -> 9 | D28: Rebar (25mm) Imported | E28: Materials | F28: =IF(ISBLANK('[1]Materials & Civils'!C13),"",'[1]Materials & Civils'!C13) -> Tonnes | G28: ='Materials & Civils'!N13 -> 9.536976 | H28: 550000 | I28: 1.672038e+08 | J28: =G28*H28 -> 5245336.8 | K28: =I28+J28 -> 1.7244914e+08
C29: ='[1]Materials & Civils'!A13 -> 9 | D29: Rebar (32mm) Imported | E29: Materials | F29: Tonne | G29: ='Materials & Civils'!N14 -> 0 | H29: 550000 | I29: 0 | J29: =G29*H29 -> 0 | K29: =I29+J29 -> 0
C30: ='[1]Materials & Civils'!A14 -> 10 | D30: Binding Wire | E30: Materials | F30: Roll | G30: ='Materials & Civils'!N15 -> 0 | H30: 14000 | I30: 252000 | J30: =G30*H30 -> 0 | K30: =I30+J30 -> 252000
C31: ='[1]Materials & Civils'!A15 -> 11 | D31: =IF(ISBLANK('[1]Materials & Civils'!B15),"",'[1]Materials & Civils'!B15) -> Sharp Sand | E31: Materials | F31: =IF(ISBLANK('[1]Materials & Civils'!C15),"",'[1]Materials & Civils'!C15) -> Tonnes | G31: ='Materials & Civils'!J16 -> 47.199421 | H31: 3000 | I31: 11495641 | J31: =G31*H31 -> 141598.26 | K31: =I31+J31 -> 11637239
C32: ='[1]Materials & Civils'!A16 -> 12 | D32: =IF(ISBLANK('[1]Materials & Civils'!B16),"",'[1]Materials & Civils'!B16) -> Blocks 9" | E32: Materials | F32: =IF(ISBLANK('[1]Materials & Civils'!C16),"",'[1]Materials & Civils'!C16) -> Each | G32: ='Materials & Civils'!J17 -> 0 | H32: 600 | I32: 1144810 | J32: =G32*H32 -> 0 | K32: =I32+J32 -> 1144810
C33: ='[1]Materials & Civils'!A17 -> 13 | D33: =IF(ISBLANK('[1]Materials & Civils'!B17),"",'[1]Materials & Civils'!B17) -> Geotextile | E33: Materials | F33: =IF(ISBLANK('[1]Materials & Civils'!C17),"",'[1]Materials & Civils'!C17) -> M2 | G33: ='Materials & Civils'!J18 -> 0 | H33: =IF(D33="",0,VLOOKUP(D33,'[1]Materials & Civils'!$B$5:$N$42,3,FALSE)) -> 1200000 | I33: 0 | J33: =G33*H33 -> 0 | K33: =I33+J33 -> 0
C34: ='[1]Materials & Civils'!A18 -> 14 | D34: =IF(ISBLANK('[1]Materials & Civils'!B18),"",'[1]Materials & Civils'!B18) -> UPVC Pipe(300mm) | E34: Materials | F34: =IF(ISBLANK('[1]Materials & Civils'!C18),"",'[1]Materials & Civils'!C18) -> Each | G34: ='Materials & Civils'!J18 -> 0 | H34: =IF(D34="",0,VLOOKUP(D34,'[1]Materials & Civils'!$B$5:$N$42,3,FALSE)) -> 2800 | I34: 0 | J34: =G34*H34 -> 0 | K34: =I34+J34 -> 0
C35: ='[1]Materials & Civils'!A19 -> 15 | D35: =IF(ISBLANK('[1]Materials & Civils'!B19),"",'[1]Materials & Civils'!B19) -> UPVC Pipe(100mm) | E35: Materials | F35: =IF(ISBLANK('[1]Materials & Civils'!C19),"",'[1]Materials & Civils'!C19) -> Each | G35: ='Materials & Civils'!J19 -> 0 | H35: =IF(D35="",0,VLOOKUP(D35,'[1]Materials & Civils'!$B$5:$N$42,3,FALSE)) -> 3800 | I35: 0 | J35: =G35*H35 -> 0 | K35: =I35+J35 -> 0
C36: ='[1]Materials & Civils'!A20 -> 16 | D36: =IF(ISBLANK('[1]Materials & Civils'!B20),"",'[1]Materials & Civils'!B20) -> Interlocking Paving Stone | E36: Materials | F36: =IF(ISBLANK('[1]Materials & Civils'!C20),"",'[1]Materials & Civils'!C20) -> m2 | G36: =IF(D36="",0,VLOOKUP(D36,'[1]Materials & Civils'!$B$5:$N$42,13,FALSE)) -> 0 | H36: =IF(D36="",0,VLOOKUP(D36,'[1]Materials & Civils'!$B$5:$N$42,3,FALSE)) -> 3600 | I36: 0 | J36: =G36*H36 -> 0 | K36: =I36+J36 -> 0
C37: ='[1]Materials & Civils'!A21 -> 17 | D37: =IF(ISBLANK('[1]Materials & Civils'!B21),"",'[1]Materials & Civils'!B21) -> Precast Units | E37: Materials | F37: =IF(ISBLANK('[1]Materials & Civils'!C21),"",'[1]Materials & Civils'!C21) -> LM | G37: =Precast!G4 -> 0 | H37: =IF(D37="",0,VLOOKUP(D37,'[1]Materials & Civils'!$B$5:$N$42,3,FALSE)) -> 25000 | I37: 0 | J37: =G37*H37 -> 0 | K37: =I37+J37 -> 0
C38: ='[1]Materials & Civils'!A25 -> QUARRY MATERIALS | F38: =IF(ISBLANK('[1]Materials & Civils'!C25),"",'[1]Materials & Civils'!C25) -> 0
C39: 18 | D39: =IF(ISBLANK('[1]Materials & Civils'!B27),"",'[1]Materials & Civils'!B27) -> 3/4" Aggregates | E39: Materials | F39: =IF(ISBLANK('[1]Materials & Civils'!C27),"",'[1]Materials & Civils'!C27) -> Tonnes | G39: ='Materials & Civils'!J23 -> 13.734023 | H39: 8350 | I39: 15196029 | J39: =G39*H39 -> 114679.09 | K39: =I39+J39 -> 15310708
C40: 19 | D40: =IF(ISBLANK('[1]Materials & Civils'!B28),"",'[1]Materials & Civils'!B28) -> 1/2" Aggregates | E40: Materials | F40: =IF(ISBLANK('[1]Materials & Civils'!C28),"",'[1]Materials & Civils'!C28) -> Tonnes | G40: ='Materials & Civils'!J22 -> 39.589687 | H40: 8350 | I40: 22873503 | J40: =G40*H40 -> 330573.89 | K40: =I40+J40 -> 23204077
...

Sheet Plant Return
A1: WEEKLY PLANT RETURNS | H1: Date: | I1: ='Contract Summary'!E1 -> 45717 | J1: Week No: | K1: =IF(I1=0,0,VLOOKUP(I1,Lists!A2:B5000,2,FALSE)) -> 9 | L1: Instructions
A2: ='Cost Report'!D2 -> PROPOSED CONSTRUCTION OF 15 SPAN, DUAL CARRIAGEWAY, 6TH BRIDGE OVER RIVER KADUNA AND APPROACH ROADS
A3: Fleet No. | B3: Description | C3: Plant Category | D3: Hours Worked | E3: S/B Hours | F3: B/D Hours | G3: Rate (N) | H3: Plant Cost | I3: Transfered From | J3: Current Location | K3: Remarks
A4: AC69 | B4: STATIC AIR COMPRESSOR | D4: 40 | E4: 30 | F4: 0 | G4: 300 | H4: =SUM(D4*G4) -> 12000 | J4: Kaduna | K4: working
A5: AC173 | B5: Mobile Air compressor | D5: 8 | E5: 62 | F5: 0 | G5: 500 | H5: =SUM(D5*G5) -> 4000 | J5: Kaduna | K5: working
A6: BB18 | B6: BAR BENDER | D6: 40 | E6: 30 | F6: 0 | G6: 500 | H6: =SUM(D6*G6) -> 20000 | J6: Kaduna | K6: working
A7: BP10 | B7: BATCHING PLANT (DRY) | D7: 40 | E7: 30 | F7: 0 | G7: 6100 | H7: =SUM(D7*G7) -> 244000 | J7: Kaduna | K7: working
A8: D67 | B8: DOZER | D8: 23 | E8: 47 | F8: 0 | G8: 8200 | H8: =SUM(D8*G8) -> 188600 | J8: Kaduna | K8: working
A9: E88 | B9: Excavator | D9: 17 | E9: 53 | F9: 0 | G9: 8200 | H9: =SUM(D9*G9) -> 139400 | J9: Kaduna
A10: E94 | B10: JS200 EXCAVATOR | D10: 44 | E10: 26 | F10: 0 | G10: 8200 | H10: =SUM(D10*G10) -> 360800 | J10: Kaduna | K10: working
A11: EG86 | B11: Generator set | D11: 34 | E11: 36 | F11: 0 | G11: 1300 | H11: =SUM(D11*G11) -> 44200 | J11: Kaduna
A12: EG214 | B12: GENERATOR SET | D12: 42 | E12: 28 | F12: 0 | G12: 1300 | H12: =SUM(D12*G12) -> 54600 | J12: Kaduna | K12: working
A13: EG251 | B13: GENERATOR SET | D13: 0 | E13: 0 | F13: 70 | G13: 1300 | H13: =SUM(D13*G13) -> 0 | J13: Kaduna | K13: Engine problem, to send to Abuja for overhaul
A14: EG252 | B14: GENERATOR SET | D14: 0 | E14: 0 | F14: 70 | G14: 1300 | H14: =SUM(D14*G14) -> 0 | J14: Kaduna | K14: Engine over consuming oil, to send to Abuja for repairs
A15: EG263 | B15: GENERATOR SET | D15: 53 | E15: 17 | F15: 0 | G15: 1300 | H15: =SUM(D15*G15) -> 68900 | J15: Kaduna | K15: working
A16: EG284 | B16: GENERATOR SET Honda | D16: 0 | E16: 70 | F16: 0 | G16: 500 | H16: =SUM(D16*G16) -> 0 | J16: Kaduna | K16: standby
A17: EG287 | B17: GENERATOR SET Firman | D17: 0 | E17: 0 | F17: 70 | G17: 500 | H17: =SUM(D17*G17) -> 0 | J17: Kaduna | K17: Nozzle problem, Not starting
A18: FMP20 | B18: FUEL METER PUMP | D18: 40 | E18: 30 | F18: 0 | G18: 500 | H18: =SUM(D18*G18) -> 20000 | J18: Kaduna | K18: working
A19: G38 | B19: Grader | D19: 0 | E19: 70 | F19: 0 | G19: 501 | H19: =SUM(D19*G19) -> 0 | J19: Kaduna
A20: IC26 | B20: IRON CUTTER | D20: 40 | E20: 30 | F20: 0 | G20: 500 | H20: =SUM(D20*G20) -> 20000 | J20: Kaduna | K20: working
A21: L66 | B21: L70F PAYLOADER | D21: 22 | E21: 48 | F21: 0 | G21: 8200 | H21: =SUM(D21*G21) -> 180400 | J21: Kaduna | K21: working
A22: L67 | B22: L150H PAYLOADER | D22: 0 | E22: 70 | F22: 0 | G22: 8200 | H22: =SUM(D22*G22) -> 0 | J22: Kaduna | K22: standby
A23: LL11 | B23: Low loader | D23: 0 | E23: 70 | F23: 0 | G23: 5800 | H23: =SUM(D23*G23) -> 0 | J23: Kaduna | K23: standby
A24: LT8 | B24: LUXURIOUS BUS | D24: 50 | E24: 20 | F24: 0 | G24: 1600 | H24: =SUM(D24*G24) -> 80000 | J24: Kaduna | K24: working
A25: MCM15 | B25: MOBILE CAR MIXER | D25: 8 | E25: 62 | F25: 0 | G25: 2000 | H25: =SUM(D25*G25) -> 16000 | J25: Kaduna | K25: working
A26: P370 | B26: PICK UP | D26: 0 | E26: 0 | F26: 70 | G26: 1000 | H26: =SUM(D26*G26) -> 0 | J26: Kaduna | K26: Injector pump and Nozzles problem
A27: P413 | B27: PICK UP | D27: 50 | E27: 20 | F27: 0 | G27: 1000 | H27: =SUM(D27*G27) -> 50000 | J27: Kaduna | K27: working
A28: P416 | B28: PICK UP | D28: 60 | E28: 10 | F28: 0 | G28: 1000 | H28: =SUM(D28*G28) -> 60000 | J28: Kaduna | K28: working
A29: P418 | B29: PICK UP | D29: 50 | E29: 20 | F29: 0 | G29: 1000 | H29: =SUM(D29*G29) -> 50000 | J29: Kaduna | K29: Propella plange yoke and cross bearing changed back to work
A30: P439 | B30: PICK UP | D30: 50 | E30: 20 | F30: 0 | G30: 1000 | H30: =SUM(D30*G30) -> 50000 | J30: Kaduna | K30: working
A31: PF5 | B31: POWER FLOAT | D31: 0 | E31: 70 | F31: 0 | H31: =SUM(D31*G31) -> 0 | J31: Kaduna | K31: standby
A32: PF6 | B32: POWER FLOAT | D32: 0 | E32: 70 | F32: 0 | H32: =SUM(D32*G32) -> 0 | J32: Kaduna | K32: standby
A33: RT12 | B33: GROVE CRANE | D33: 15 | E33: 55 | F33: 0 | G33: 13200 | H33: =SUM(D33*G33) -> 198000 | J33: Kaduna | K33: working
A34: T210 | B34: WATER TANKER | D34: 40 | E34: 30 | F34: 0 | G34: 4100 | H34: =SUM(D34*G34) -> 164000 | J34: Kaduna | K34: working
A35: T229 | B35: WATER TANKER | D35: 40 | E35: 30 | F35: 0 | G35: 4100 | H35: =SUM(D35*G35) -> 164000 | J35: Kaduna | K35: working
A36: T343 | B36: Low loader | D36: 0 | E36: 70 | F36: 0 | G36: 4900 | H36: =SUM(D36*G36) -> 0 | J36: Kaduna | K36: standby
A37: T365 | B37: TRACTOR UNIT | D37: 50 | E37: 20 | F37: 0 | G37: 4900 | H37: =SUM(D37*G37) -> 245000 | J37: Kaduna | K37: working
A38: T385 | B38: TRUCK MIXER | D38: 50 | E38: 20 | F38: 0 | G38: 4900 | H38: =SUM(D38*G38) -> 245000 | J38: Kaduna | K38: working
A39: T403 | B39: Concrete Pump | D39: 0 | E39: 70 | F39: 0 | H39: =SUM(D39*G39) -> 0 | J39: Kaduna | K39: standby
A40: T488 | B40: FUEL BOWSER | D40: 8 | E40: 62 | F40: 0 | G40: 5800 | H40: =SUM(D40*G40) -> 46400 | J40: Kaduna | K40: working
...

Sheet Diesel Consumption
A1: WEEKLY DIESEL CONSUMPTION | G1: Date: | H1: ='Contract Summary'!E1 -> 45717 | N1: Week No: | O1: =IF(H1=0,0,VLOOKUP(H1,Lists!A2:B5000,2,FALSE)) -> 9 | R1: Instructions
A2: ='Plant Return'!A2 -> PROPOSED CONSTRUCTION OF 15 SPAN, DUAL CARRIAGEWAY, 6TH BRIDGE OVER RIVER KADUNA AND APPROACH ROADS
C3: Opening Stock: | D3: 0 | H3: Received this Week: | I3: 0 | L3: Used This Week: | M3: =K87 -> 2193 | P3: Closing Stock: | Q3: =D3+I3-M3 -> -2193
A4: Fleet No. | B4: Description | C4: Plant Category | D4: Saturday | E4: Sunday | F4: Monday | G4: Tuesday | H4: Wednesday | I4: Thursday | J4: Friday | K4: Total Fuel Taken | L4: Standard Ltrs/Hour | M4: Standard Usage | N4: Variance | O4: Variance Value | P4: Usage Value | Q4: Remarks
A5: AC69 | B5: STATIC AIR COMPRESSOR | D5: 0 | E5: 0 | F5: 0 | G5: 0 | H5: 0 | I5: 0 | J5: 0 | K5: =D5+E5+F5+G5+H5+I5+J5 -> 0 | L5: 0 | M5: =IF(A5="",0,VLOOKUP(A5,'Plant Return'!$A$4:$D$62,4,FALSE)*L5) -> 0 | N5: =K5-M5 -> 0 | O5: =N5*'Cost Report'!$H$5 -> 0 | P5: =K5*'Cost Report'!$H$5 -> 0
A6: AC173 | B6: Mobile Air compressor | D6: 0 | E6: 0 | F6: 0 | G6: 0 | H6: 0 | I6: 0 | J6: 0 | K6: =D6+E6+F6+G6+H6+I6+J6 -> 0 | L6: 0 | M6: =IF(A6="",0,VLOOKUP(A6,'Plant Return'!$A$4:$D$62,4,FALSE)*L6) -> 0 | N6: =K6-M6 -> 0 | O6: =N6*'Cost Report'!$H$5 -> 0 | P6: =K6*'Cost Report'!$H$5 -> 0
A7: BB18 | B7: BAR BENDER | D7: 0 | E7: 0 | F7: 0 | G7: 0 | H7: 0 | I7: 0 | J7: 0 | K7: =D7+E7+F7+G7+H7+I7+J7 -> 0 | M7: =IF(A7="",0,VLOOKUP(A7,'Plant Return'!$A$4:$D$62,4,FALSE)*L7) -> 0 | N7: =K7-M7 -> 0 | O7: =N7*'Cost Report'!$H$5 -> 0 | P7: =K7*'Cost Report'!$H$5 -> 0
A8: BP10 | B8: BATCHING PLANT (DRY) | D8: 0 | E8: 0 | F8: 0 | G8: 0 | H8: 0 | I8: 0 | J8: 0 | K8: =D8+E8+F8+G8+H8+I8+J8 -> 0 | M8: =IF(A8="",0,VLOOKUP(A8,'Plant Return'!$A$4:$D$62,4,FALSE)*L8) -> 0 | N8: =K8-M8 -> 0 | O8: =N8*'Cost Report'!$H$5 -> 0 | P8: =K8*'Cost Report'!$H$5 -> 0
A9: D67 | B9: DOZER | D9: 0 | E9: 0 | F9: 100 | G9: 0 | H9: 50 | I9: 100 | J9: 50 | K9: =D9+E9+F9+G9+H9+I9+J9 -> 300 | M9: =IF(A9="",0,VLOOKUP(A9,'Plant Return'!$A$4:$D$62,4,FALSE)*L9) -> 0 | N9: =K9-M9 -> 300 | O9: =N9*'Cost Report'!$H$5 -> 330000 | P9: =K9*'Cost Report'!$H$5 -> 330000
A10: E88 | B10: Excavator | D10: 0 | E10: 0 | F10: 50 | G10: 0 | H10: 50 | I10: 80 | J10: 60 | K10: =D10+E10+F10+G10+H10+I10+J10 -> 240 | M10: =IF(A10="",0,VLOOKUP(A10,'Plant Return'!$A$4:$D$62,4,FALSE)*L10) -> 0 | N10: =K10-M10 -> 240 | O10: =N10*'Cost Report'!$H$5 -> 264000 | P10: =K10*'Cost Report'!$H$5 -> 264000
